<sdf version='1.6'>
  <model name='centipede'>
    <link name='base_link'>
      <pose frame=''>0 0 0 0 -0 0</pose>
      <inertial>
        <pose frame=''>0 0 0.4 0 -0 0</pose>
        <mass>1</mass>
        <inertia>
          <ixx>0.004</ixx>
          <ixy>0</ixy>
          <ixz>0</ixz>
          <iyy>0.004</iyy>
          <iyz>0</iyz>
          <izz>0.004</izz>
        </inertia>
      </inertial>
      <collision name='base_link_fixed_joint_lump__body1_collision'>
        <pose frame=''>0 0 0.4 0 -0 0</pose>
        <geometry>
          <sphere>
            <radius>0.1</radius>
          </sphere>
        </geometry>
        <surface>
          <contact>
            <ode/>
          </contact>
          <friction>
            <ode/>
          </friction>
        </surface>
      </collision>
      <visual name='base_link_fixed_joint_lump__body1_visual'>
        <pose frame=''>0 0 0.4 0 -0 0</pose>
        <geometry>
          <sphere>
            <radius>0.1</radius>
          </sphere>
        </geometry>
        <material>
          <script>
            <name>Gazebo/Orange</name>
            <uri>file://media/materials/scripts/gazebo.material</uri>
          </script>
        </material>
      </visual>
      <gravity>1</gravity>
      <velocity_decay/>
    </link>
    <link name='base_left_1'>
      <pose frame=''>0 0.1 0.4 0 -0 1.5708</pose>
      <inertial>
        <pose frame=''>0 0 0 0 -0 0</pose>
        <mass>0.5</mass>
        <inertia>
          <ixx>0.000125</ixx>
          <ixy>0</ixy>
          <ixz>0</ixz>
          <iyy>0.000125</iyy>
          <iyz>0</iyz>
          <izz>0.000125</izz>
        </inertia>
      </inertial>
      <collision name='base_left_1_collision'>
        <pose frame=''>0 0 0 0 -0 0</pose>
        <geometry>
          <sphere>
            <radius>0.025</radius>
          </sphere>
        </geometry>
        <surface>
          <contact>
            <ode/>
          </contact>
          <friction>
            <ode/>
          </friction>
        </surface>
      </collision>
      <visual name='base_left_1_visual'>
        <pose frame=''>0 0 0 0 -0 0</pose>
        <geometry>
          <sphere>
            <radius>0.025</radius>
          </sphere>
        </geometry>
        <material>
          <script>
            <name>Gazebo/Black</name>
            <uri>file://media/materials/scripts/gazebo.material</uri>
          </script>
        </material>
      </visual>
      <gravity>1</gravity>
      <velocity_decay/>
      <self_collide>0</self_collide>
    </link>
    <joint name='hinge_left_1_1' type='revolute'>
      <child>base_left_1</child>
      <parent>base_link</parent>
      <axis>
        <xyz>0 0 1</xyz>
        <limit>
          <lower>-0.392688</lower>
          <upper>0.785</upper>
          <effort>1000</effort>
          <velocity>100</velocity>
        </limit>
        <dynamics>
          <spring_reference>0</spring_reference>
          <spring_stiffness>0</spring_stiffness>
        </dynamics>
        <use_parent_model_frame>1</use_parent_model_frame>
      </axis>
    </joint>
    <link name='link_left_1_upper'>
      <pose frame=''>0 0.1 0.4 0 1.5707 1.5708</pose>
      <inertial>
        <pose frame=''>0 0 0.06 0 -0 0</pose>
        <mass>2.5</mass>
        <inertia>
          <ixx>0.00304896</ixx>
          <ixy>0</ixy>
          <ixz>0</ixz>
          <iyy>0.00302292</iyy>
          <iyz>2.50851e-09</iyz>
          <izz>0.000582292</izz>
        </inertia>
      </inertial>
      <collision name='link_left_1_upper_collision'>
        <pose frame=''>0 0 0.05 0 -0 0</pose>
        <geometry>
          <cylinder>
            <length>0.1</length>
            <radius>0.02</radius>
          </cylinder>
        </geometry>
        <surface>
          <contact>
            <ode>
              <kp>1e+07</kp>
              <kd>1</kd>
            </ode>
          </contact>
          <friction>
            <ode>
              <mu>10000</mu>
              <mu2>10000</mu2>
              <fdir1>1 0 0</fdir1>
            </ode>
          </friction>
        </surface>
      </collision>
      <collision name='link_left_1_upper_fixed_joint_lump__serbo_left_1_collision_1'>
        <pose frame=''>0 0 0.1 1.5707 -0 0</pose>
        <geometry>
          <cylinder>
            <length>0.05</length>
            <radius>0.025</radius>
          </cylinder>
        </geometry>
        <surface>
          <contact>
            <ode>
              <kp>1e+07</kp>
              <kd>1</kd>
            </ode>
          </contact>
          <friction>
            <ode>
              <mu>10000</mu>
              <mu2>10000</mu2>
              <fdir1>1 0 0</fdir1>
            </ode>
          </friction>
        </surface>
      </collision>
      <visual name='link_left_1_upper_visual'>
        <pose frame=''>0 0 0.05 0 -0 0</pose>
        <geometry>
          <cylinder>
            <length>0.1</length>
            <radius>0.02</radius>
          </cylinder>
        </geometry>
        <material>
          <script>
            <name>Gazebo/Gray</name>
            <uri>file://media/materials/scripts/gazebo.material</uri>
          </script>
        </material>
      </visual>
      <visual name='link_left_1_upper_fixed_joint_lump__serbo_left_1_visual_1'>
        <pose frame=''>0 0 0.1 1.5707 -0 0</pose>
        <geometry>
          <cylinder>
            <length>0.05</length>
            <radius>0.025</radius>
          </cylinder>
        </geometry>
        <material>
          <script>
            <name>Gazebo/Black</name>
            <uri>file://media/materials/scripts/gazebo.material</uri>
          </script>
        </material>
      </visual>
      <velocity_decay/>
      <gravity>1</gravity>
      <velocity_decay/>
      <self_collide>0</self_collide>
    </link>
    <joint name='hinge_left_1_2' type='revolute'>
      <child>link_left_1_upper</child>
      <parent>base_left_1</parent>
      <axis>
        <xyz>-1 0 -0</xyz>
        <limit>
          <lower>-0.1963</lower>
          <upper>0.1963</upper>
          <effort>1000</effort>
          <velocity>100</velocity>
        </limit>
        <dynamics>
          <spring_reference>0</spring_reference>
          <spring_stiffness>0</spring_stiffness>
        </dynamics>
        <use_parent_model_frame>1</use_parent_model_frame>
      </axis>
    </joint>
    <link name='link_left_1_lower'>
      <pose frame=''>0 0.2 0.40001 3.1415 9.6e-05 -3.1415</pose>
      <inertial>
        <pose frame=''>0 0 0.050495 0 -0 0</pose>
        <mass>2.02</mass>
        <inertia>
          <ixx>0.00176937</ixx>
          <ixy>0</ixy>
          <ixz>0</ixz>
          <iyy>0.00176937</iyy>
          <iyz>0</iyz>
          <izz>0.0001032</izz>
        </inertia>
      </inertial>
      <collision name='link_left_1_lower_collision'>
        <pose frame=''>0 0 0.05 0 -0 0</pose>
        <geometry>
          <cylinder>
            <length>0.1</length>
            <radius>0.01</radius>
          </cylinder>
        </geometry>
        <surface>
          <contact>
            <ode>
              <kp>1e+07</kp>
              <kd>1</kd>
            </ode>
          </contact>
          <friction>
            <ode>
              <mu>10000</mu>
              <mu2>10000</mu2>
              <fdir1>1 0 0</fdir1>
            </ode>
          </friction>
        </surface>
      </collision>
      <collision name='link_left_1_lower_fixed_joint_lump__ball_left_1_collision_1'>
        <pose frame=''>0 0 0.1 0 -0 0</pose>
        <geometry>
          <sphere>
            <radius>0.02</radius>
          </sphere>
        </geometry>
        <surface>
          <contact>
            <ode>
              <kp>1e+07</kp>
              <kd>1</kd>
            </ode>
          </contact>
          <friction>
            <ode>
              <mu>10000</mu>
              <mu2>10000</mu2>
              <fdir1>1 0 0</fdir1>
            </ode>
          </friction>
        </surface>
      </collision>
      <visual name='link_left_1_lower_visual'>
        <pose frame=''>0 0 0.05 0 -0 0</pose>
        <geometry>
          <cylinder>
            <length>0.1</length>
            <radius>0.01</radius>
          </cylinder>
        </geometry>
        <material>
          <script>
            <name>Gazebo/Gray</name>
            <uri>file://media/materials/scripts/gazebo.material</uri>
          </script>
        </material>
      </visual>
      <visual name='link_left_1_lower_fixed_joint_lump__ball_left_1_visual_1'>
        <pose frame=''>0 0 0.1 0 -0 0</pose>
        <geometry>
          <sphere>
            <radius>0.02</radius>
          </sphere>
        </geometry>
        <material>
          <script>
            <name>Gazebo/Black</name>
            <uri>file://media/materials/scripts/gazebo.material</uri>
          </script>
        </material>
      </visual>
      <velocity_decay/>
      <gravity>1</gravity>
      <velocity_decay/>
      <self_collide>0</self_collide>
    </link>
    <joint name='hinge_left_1_3' type='revolute'>
      <child>link_left_1_lower</child>
      <parent>link_left_1_upper</parent>
      <axis>
        <xyz>-1 -9.6e-05 -9.6e-05</xyz>
        <limit>
          <lower>-0.785</lower>
          <upper>0.785</upper>
          <effort>1000</effort>
          <velocity>100</velocity>
        </limit>
        <dynamics>
          <spring_reference>0</spring_reference>
          <spring_stiffness>0</spring_stiffness>
        </dynamics>
        <use_parent_model_frame>1</use_parent_model_frame>
      </axis>
    </joint>
    <link name='base_right_1'>
      <pose frame=''>0 -0.1 0.4 0 -0 -1.5708</pose>
      <inertial>
        <pose frame=''>0 0 0 0 -0 0</pose>
        <mass>0.5</mass>
        <inertia>
          <ixx>0.000125</ixx>
          <ixy>0</ixy>
          <ixz>0</ixz>
          <iyy>0.000125</iyy>
          <iyz>0</iyz>
          <izz>0.000125</izz>
        </inertia>
      </inertial>
      <collision name='base_right_1_collision'>
        <pose frame=''>0 0 0 0 -0 0</pose>
        <geometry>
          <sphere>
            <radius>0.025</radius>
          </sphere>
        </geometry>
        <surface>
          <contact>
            <ode/>
          </contact>
          <friction>
            <ode/>
          </friction>
        </surface>
      </collision>
      <visual name='base_right_1_visual'>
        <pose frame=''>0 0 0 0 -0 0</pose>
        <geometry>
          <sphere>
            <radius>0.025</radius>
          </sphere>
        </geometry>
        <material>
          <script>
            <name>Gazebo/Black</name>
            <uri>file://media/materials/scripts/gazebo.material</uri>
          </script>
        </material>
      </visual>
      <gravity>1</gravity>
      <velocity_decay/>
      <self_collide>0</self_collide>
    </link>
    <joint name='hinge_right_1_1' type='revolute'>
      <child>base_right_1</child>
      <parent>base_link</parent>
      <axis>
        <xyz>0 0 1</xyz>
        <limit>
          <lower>-0.392688</lower>
          <upper>0.785</upper>
          <effort>1000</effort>
          <velocity>100</velocity>
        </limit>
        <dynamics>
          <spring_reference>0</spring_reference>
          <spring_stiffness>0</spring_stiffness>
        </dynamics>
        <use_parent_model_frame>1</use_parent_model_frame>
      </axis>
    </joint>
    <link name='link_right_1_upper'>
      <pose frame=''>0 -0.1 0.4 0 1.5707 -1.5708</pose>
      <inertial>
        <pose frame=''>0 0 0.06 0 -0 0</pose>
        <mass>2.5</mass>
        <inertia>
          <ixx>0.00304896</ixx>
          <ixy>0</ixy>
          <ixz>0</ixz>
          <iyy>0.00302292</iyy>
          <iyz>2.50851e-09</iyz>
          <izz>0.000582292</izz>
        </inertia>
      </inertial>
      <collision name='link_right_1_upper_collision'>
        <pose frame=''>0 0 0.05 0 -0 0</pose>
        <geometry>
          <cylinder>
            <length>0.1</length>
            <radius>0.02</radius>
          </cylinder>
        </geometry>
        <surface>
          <contact>
            <ode>
              <kp>1e+07</kp>
              <kd>1</kd>
            </ode>
          </contact>
          <friction>
            <ode>
              <mu>10000</mu>
              <mu2>10000</mu2>
              <fdir1>1 0 0</fdir1>
            </ode>
          </friction>
        </surface>
      </collision>
      <collision name='link_right_1_upper_fixed_joint_lump__serbo_right_1_collision_1'>
        <pose frame=''>0 0 0.1 1.5707 -0 0</pose>
        <geometry>
          <cylinder>
            <length>0.05</length>
            <radius>0.025</radius>
          </cylinder>
        </geometry>
        <surface>
          <contact>
            <ode>
              <kp>1e+07</kp>
              <kd>1</kd>
            </ode>
          </contact>
          <friction>
            <ode>
              <mu>10000</mu>
              <mu2>10000</mu2>
              <fdir1>1 0 0</fdir1>
            </ode>
          </friction>
        </surface>
      </collision>
      <visual name='link_right_1_upper_visual'>
        <pose frame=''>0 0 0.05 0 -0 0</pose>
        <geometry>
          <cylinder>
            <length>0.1</length>
            <radius>0.02</radius>
          </cylinder>
        </geometry>
        <material>
          <script>
            <name>Gazebo/Gray</name>
            <uri>file://media/materials/scripts/gazebo.material</uri>
          </script>
        </material>
      </visual>
      <visual name='link_right_1_upper_fixed_joint_lump__serbo_right_1_visual_1'>
        <pose frame=''>0 0 0.1 1.5707 -0 0</pose>
        <geometry>
          <cylinder>
            <length>0.05</length>
            <radius>0.025</radius>
          </cylinder>
        </geometry>
        <material>
          <script>
            <name>Gazebo/Black</name>
            <uri>file://media/materials/scripts/gazebo.material</uri>
          </script>
        </material>
      </visual>
      <velocity_decay/>
      <gravity>1</gravity>
      <velocity_decay/>
      <self_collide>0</self_collide>
    </link>
    <joint name='hinge_right_1_2' type='revolute'>
      <child>link_right_1_upper</child>
      <parent>base_right_1</parent>
      <axis>
        <xyz>1 -0 -0</xyz>
        <limit>
          <lower>-0.1963</lower>
          <upper>0.1963</upper>
          <effort>1000</effort>
          <velocity>100</velocity>
        </limit>
        <dynamics>
          <spring_reference>0</spring_reference>
          <spring_stiffness>0</spring_stiffness>
        </dynamics>
        <use_parent_model_frame>1</use_parent_model_frame>
      </axis>
    </joint>
    <link name='link_right_1_lower'>
      <pose frame=''>-0 -0.2 0.40001 3.1415 9.6e-05 9.6e-05</pose>
      <inertial>
        <pose frame=''>0 0 0.050495 0 -0 0</pose>
        <mass>2.02</mass>
        <inertia>
          <ixx>0.00176937</ixx>
          <ixy>0</ixy>
          <ixz>0</ixz>
          <iyy>0.00176937</iyy>
          <iyz>0</iyz>
          <izz>0.0001032</izz>
        </inertia>
      </inertial>
      <collision name='link_right_1_lower_collision'>
        <pose frame=''>0 0 0.05 0 -0 0</pose>
        <geometry>
          <cylinder>
            <length>0.1</length>
            <radius>0.01</radius>
          </cylinder>
        </geometry>
        <surface>
          <contact>
            <ode>
              <kp>1e+07</kp>
              <kd>1</kd>
            </ode>
          </contact>
          <friction>
            <ode>
              <mu>10000</mu>
              <mu2>10000</mu2>
              <fdir1>1 0 0</fdir1>
            </ode>
          </friction>
        </surface>
      </collision>
      <collision name='link_right_1_lower_fixed_joint_lump__ball_right_1_collision_1'>
        <pose frame=''>0 0 0.1 0 -0 0</pose>
        <geometry>
          <sphere>
            <radius>0.02</radius>
          </sphere>
        </geometry>
        <surface>
          <contact>
            <ode>
              <kp>1e+07</kp>
              <kd>1</kd>
            </ode>
          </contact>
          <friction>
            <ode>
              <mu>10000</mu>
              <mu2>10000</mu2>
              <fdir1>1 0 0</fdir1>
            </ode>
          </friction>
        </surface>
      </collision>
      <visual name='link_right_1_lower_visual'>
        <pose frame=''>0 0 0.05 0 -0 0</pose>
        <geometry>
          <cylinder>
            <length>0.1</length>
            <radius>0.01</radius>
          </cylinder>
        </geometry>
        <material>
          <script>
            <name>Gazebo/Gray</name>
            <uri>file://media/materials/scripts/gazebo.material</uri>
          </script>
        </material>
      </visual>
      <visual name='link_right_1_lower_fixed_joint_lump__ball_right_1_visual_1'>
        <pose frame=''>0 0 0.1 0 -0 0</pose>
        <geometry>
          <sphere>
            <radius>0.02</radius>
          </sphere>
        </geometry>
        <material>
          <script>
            <name>Gazebo/Black</name>
            <uri>file://media/materials/scripts/gazebo.material</uri>
          </script>
        </material>
      </visual>
      <velocity_decay/>
      <gravity>1</gravity>
      <velocity_decay/>
      <self_collide>0</self_collide>
    </link>
    <joint name='hinge_right_1_3' type='revolute'>
      <child>link_right_1_lower</child>
      <parent>link_right_1_upper</parent>
      <axis>
        <xyz>1 9.6e-05 -9.6e-05</xyz>
        <limit>
          <lower>-0.785</lower>
          <upper>0.785</upper>
          <effort>1000</effort>
          <velocity>100</velocity>
        </limit>
        <dynamics>
          <spring_reference>0</spring_reference>
          <spring_stiffness>0</spring_stiffness>
        </dynamics>
        <use_parent_model_frame>1</use_parent_model_frame>
      </axis>
    </joint>
  </model>
</sdf>
