<?xml version="1.0" encoding="utf-8"?>
<!-- =================================================================================== -->
<!-- |    This document was autogenerated by xacro from centipede.urdf.xacro           | -->
<!-- |    EDITING THIS FILE BY HAND IS NOT RECOMMENDED                                 | -->
<!-- =================================================================================== -->
<!--  Centipede bot-->
<robot name="centipede">
  <!--  <!- - ros_control plugin - ->
  <gazebo>
    <plugin name="gazebo_ros_control" filename="libgazebo_ros_control.so">
      <robotNamespace>/centipede</robotNamespace>
      <robotSimType>gazebo_ros_control/DefaultRobotHWSim</robotSimType>
    </plugin>
  </gazebo>-->
  <!-- Link1 -->
  <gazebo reference="body1">
    <material>Gazebo/Orange</material>
  </gazebo>
  <!-- Link2 -->
  <gazebo reference="link2">
    <mu1>0.2</mu1>
    <mu2>0.2</mu2>
    <material>Gazebo/Black</material>
  </gazebo>
  <!-- Link3 -->
  <gazebo reference="link3">
    <mu1>0.2</mu1>
    <mu2>0.2</mu2>
    <material>Gazebo/Orange</material>
  </gazebo>
  <material name="black">
    <color rgba="0.0 0.0 0.0 1.0"/>
  </material>
  <material name="blue">
    <color rgba="0.0 0.0 0.8 1.0"/>
  </material>
  <material name="green">
    <color rgba="0.0 0.8 0.0 1.0"/>
  </material>
  <material name="grey">
    <color rgba="0.2 0.2 0.2 1.0"/>
  </material>
  <material name="orange">
    <color rgba="1.0 0.423529411765 0.0392156862745 1.0"/>
  </material>
  <material name="brown">
    <color rgba="0.870588235294 0.811764705882 0.764705882353 1.0"/>
  </material>
  <material name="red">
    <color rgba="0.8 0.0 0.0 1.0"/>
  </material>
  <material name="white">
    <color rgba="1.0 1.0 1.0 1.0"/>
  </material>
  <!-- Used for fixing robot to Gazebo 'base_link (frame reference)' -->
  <link name="base_link"/>
  <joint name="fixed" type="fixed">
    <parent link="base_link"/>
    <child link="body1"/>
  </joint>
  <!-- Base Link -->
  <!-- TODO: Generalize body1Origin -->
  <link name="body1">
    <collision>
      <origin rpy="0 0 0" xyz="0 0 0.4"/>
      <geometry>
        <sphere radius="0.1"/>
      </geometry>
    </collision>
    <visual>
      <origin rpy="0 0 0" xyz="0 0 0.4"/>
      <geometry>
        <sphere radius="0.1"/>
      </geometry>
      <material name="orange"/>
    </visual>
    <inertial>
      <origin rpy="0 0 0" xyz="0 0 0.4"/>
      <mass value="1"/>
      <inertia ixx="0.004" ixy="0" ixz="0" iyy="0.004" iyz="0" izz="0.004"/>
    </inertial>
  </link>
  <!--number : number of body ; lr: left, right -->
  <!--1st joint Body-Leg -->
  <joint name="hinge_left_1_1" type="revolute">
    <parent link="body1"/>
    <child link="base_left_1"/>
    <origin rpy="0 0 1.57079632679" xyz="0.0 0.1 0.4"/>
    <axis xyz="0 0 1"/>
    <limit effort="1000" lower="-0.3926875" upper="0.785" velocity="100.0"/>
  </joint>
  <!-- Leg base -->
  <link name="base_left_1">
    <visual>
      <geometry>
        <sphere radius="0.025"/>
      </geometry>
      <material name="Black"/>
    </visual>
    <collision>
      <origin rpy="0 0 0 " xyz="0 0 0"/>
      <geometry>
        <sphere radius="0.025"/>
      </geometry>
    </collision>
    <inertial>
      <origin xyz="0 0 0"/>
      <mass value="0.5"/>
      <inertia ixx="0.000125" ixy="0" ixz="0" iyy="0.000125" iyz="0" izz="0.000125"/>
    </inertial>
  </link>
  <!--2nd joint-->
  <joint name="hinge_left_1_2" type="revolute">
    <parent link="base_left_1"/>
    <child link="link_left_1_upper"/>
    <origin rpy="0 1.5707 0" xyz="0 0 0"/>
    <axis xyz="0 1 0"/>
    <limit effort="1000" lower="-0.1963" upper="0.1963" velocity="100.0"/>
  </joint>
  <!-- Femur -->
  <link name="link_left_1_upper">
    <inertial>
      <origin xyz="0 0 0.05"/>
      <mass value="2.0"/>
      <inertia ixx="0.00186666666667" ixy="0" ixz="0" iyy="0.00186666666667" iyz="0" izz="0.0004"/>
    </inertial>
    <collision>
      <origin rpy="0 0 0" xyz="0 0 0.05"/>
      <geometry>
        <cylinder length="0.1" radius="0.02"/>
      </geometry>
    </collision>
    <visual>
      <origin rpy="0 0 0" xyz="0 0 0.05"/>
      <geometry>
        <cylinder length="0.1" radius="0.02"/>
      </geometry>
      <material name="Gray"/>
    </visual>
  </link>
  <joint name="serbo_left_1_joint" type="fixed">
    <parent link="link_left_1_upper"/>
    <child link="serbo_left_1"/>
    <origin rpy="1.5707 0 0" xyz="0 0 0.1"/>
  </joint>
  <link name="serbo_left_1">
    <visual>
      <geometry>
        <cylinder length="0.05" radius="0.025"/>
      </geometry>
      <material name="Black"/>
    </visual>
    <collision>
      <origin rpy="0 0 0 " xyz="0 0 0"/>
      <geometry>
        <cylinder length="0.05" radius="0.025"/>
      </geometry>
    </collision>
    <inertial>
      <origin xyz="0 0 0"/>
      <mass value="0.5"/>
      <inertia ixx="0.000182291666667" ixy="0" ixz="0" iyy="0.000182291666667" iyz="0" izz="0.00015625"/>
    </inertial>
  </link>
  <!--3rd joint: Upper-Lower -->
  <joint name="hinge_left_1_3" type="revolute">
    <parent link="serbo_left_1"/>
    <child link="link_left_1_lower"/>
    <origin rpy="0 1.5707 0" xyz="0 0 0"/>
    <axis xyz="1 0 0"/>
    <limit effort="1000" lower="-0.785" upper="0.785" velocity="100.0"/>
  </joint>
  <link name="link_left_1_lower">
    <inertial>
      <origin xyz="0 0 0.05"/>
      <mass value="2.0"/>
      <inertia ixx="0.00171666666667" ixy="0" ixz="0" iyy="0.00171666666667" iyz="0" izz="0.0001"/>
    </inertial>
    <collision>
      <origin rpy="0 0 0" xyz="0 0 0.05"/>
      <geometry>
        <cylinder length="0.1" radius="0.01"/>
      </geometry>
    </collision>
    <visual>
      <origin rpy="0 0 0" xyz="0 0 0.05"/>
      <geometry>
        <cylinder length="0.1" radius="0.01"/>
      </geometry>
      <material name="Gray"/>
    </visual>
  </link>
  <link name="ball_left_1">
    <visual>
      <geometry>
        <sphere radius="0.02"/>
      </geometry>
      <material name="Black"/>
    </visual>
    <collision>
      <origin rpy="0 0 0 " xyz="0 0 0"/>
      <geometry>
        <sphere radius="0.02"/>
      </geometry>
    </collision>
    <inertial>
      <origin xyz="0 0 0"/>
      <mass value="0.02"/>
      <inertia ixx="3.2e-06" ixy="0" ixz="0" iyy="3.2e-06" iyz="0" izz="3.2e-06"/>
    </inertial>
  </link>
  <joint name="ball_left_1_joint" type="fixed">
    <parent link="link_left_1_lower"/>
    <child link="ball_left_1"/>
    <origin rpy="0 0 0" xyz="0 0 0.1"/>
  </joint>
  <!--joint-->
  <!-- =========gazebo reference============ -->
  <gazebo reference="base_left_1">
    <selfCollide value="false"/>
    <material>Gazebo/Black</material>
    <turnGravityOff>false</turnGravityOff>
  </gazebo>
  <gazebo reference="link_left_1_lower">
    <selfCollide value="false"/>
    <mu1 value="10000.0"/>
    <mu2 value="10000.0"/>
    <kp value="10000000.0"/>
    <kd value="1.0"/>
    <fdir1 value="1 0 0"/>
    <material>Gazebo/Gray</material>
    <turnGravityOff>false</turnGravityOff>
  </gazebo>
  <gazebo reference="link_left_1_upper">
    <selfCollide value="false"/>
    <mu1 value="10000.0"/>
    <mu2 value="10000.0"/>
    <kp value="10000000.0"/>
    <kd value="1.0"/>
    <fdir1 value="1 0 0"/>
    <material>Gazebo/Gray</material>
    <turnGravityOff>false</turnGravityOff>
  </gazebo>
  <gazebo reference="ball_left_1">
    <selfCollide value="false"/>
    <mu1 value="10000.0"/>
    <mu2 value="10000.0"/>
    <kp value="10000000.0"/>
    <kd value="1.0"/>
    <fdir1 value="1 0 0"/>
    <material>Gazebo/Black</material>
    <turnGravityOff>false</turnGravityOff>
  </gazebo>
  <gazebo reference="serbo_left_1">
    <selfCollide value="false"/>
    <mu1 value="10000.0"/>
    <mu2 value="10000.0"/>
    <kp value="10000000.0"/>
    <kd value="1.0"/>
    <fdir1 value="1 0 0"/>
    <material>Gazebo/Black</material>
    <turnGravityOff>false</turnGravityOff>
  </gazebo>
  <!-- Transmission is important to link the joints and the controller -->
  <transmission name="hinge_left_1_1_trans">
    <type>transmission_interface/SimpleTransmission</type>
    <joint name="hinge_left_1_1">
      <hardwareInterface>hardware_interface/EffortJointInterface</hardwareInterface>
    </joint>
    <actuator name="hinge_left_1_1_motor">
      <mechanicalReduction>1</mechanicalReduction>
    </actuator>
  </transmission>
  <transmission name="hinge_left_1_2_trans">
    <type>transmission_interface/SimpleTransmission</type>
    <joint name="hinge_left_1_2">
      <hardwareInterface>hardware_interface/EffortJointInterface</hardwareInterface>
    </joint>
    <actuator name="hinge_left_1_2_motor">
      <mechanicalReduction>1</mechanicalReduction>
    </actuator>
  </transmission>
  <transmission name="hinge_left_1_3_trans">
    <type>transmission_interface/SimpleTransmission</type>
    <joint name="hinge_left_1_3">
      <hardwareInterface>hardware_interface/EffortJointInterface</hardwareInterface>
    </joint>
    <actuator name="hinge_left_1_3_motor">
      <mechanicalReduction>1</mechanicalReduction>
    </actuator>
  </transmission>
  <!--number : number of body ; lr: left, right -->
  <!--1st joint Body-Leg -->
  <joint name="hinge_right_1_1" type="revolute">
    <parent link="body1"/>
    <child link="base_right_1"/>
    <origin rpy="0 0 4.71238898038" xyz="0.0 -0.1 0.4"/>
    <axis xyz="0 0 1"/>
    <limit effort="1000" lower="-0.3926875" upper="0.785" velocity="100.0"/>
  </joint>
  <!-- Leg base -->
  <link name="base_right_1">
    <visual>
      <geometry>
        <sphere radius="0.025"/>
      </geometry>
      <material name="Black"/>
    </visual>
    <collision>
      <origin rpy="0 0 0 " xyz="0 0 0"/>
      <geometry>
        <sphere radius="0.025"/>
      </geometry>
    </collision>
    <inertial>
      <origin xyz="0 0 0"/>
      <mass value="0.5"/>
      <inertia ixx="0.000125" ixy="0" ixz="0" iyy="0.000125" iyz="0" izz="0.000125"/>
    </inertial>
  </link>
  <!--2nd joint-->
  <joint name="hinge_right_1_2" type="revolute">
    <parent link="base_right_1"/>
    <child link="link_right_1_upper"/>
    <origin rpy="0 1.5707 0" xyz="0 0 0"/>
    <axis xyz="0 1 0"/>
    <limit effort="1000" lower="-0.1963" upper="0.1963" velocity="100.0"/>
  </joint>
  <!-- Femur -->
  <link name="link_right_1_upper">
    <inertial>
      <origin xyz="0 0 0.05"/>
      <mass value="2.0"/>
      <inertia ixx="0.00186666666667" ixy="0" ixz="0" iyy="0.00186666666667" iyz="0" izz="0.0004"/>
    </inertial>
    <collision>
      <origin rpy="0 0 0" xyz="0 0 0.05"/>
      <geometry>
        <cylinder length="0.1" radius="0.02"/>
      </geometry>
    </collision>
    <visual>
      <origin rpy="0 0 0" xyz="0 0 0.05"/>
      <geometry>
        <cylinder length="0.1" radius="0.02"/>
      </geometry>
      <material name="Gray"/>
    </visual>
  </link>
  <joint name="serbo_right_1_joint" type="fixed">
    <parent link="link_right_1_upper"/>
    <child link="serbo_right_1"/>
    <origin rpy="1.5707 0 0" xyz="0 0 0.1"/>
  </joint>
  <link name="serbo_right_1">
    <visual>
      <geometry>
        <cylinder length="0.05" radius="0.025"/>
      </geometry>
      <material name="Black"/>
    </visual>
    <collision>
      <origin rpy="0 0 0 " xyz="0 0 0"/>
      <geometry>
        <cylinder length="0.05" radius="0.025"/>
      </geometry>
    </collision>
    <inertial>
      <origin xyz="0 0 0"/>
      <mass value="0.5"/>
      <inertia ixx="0.000182291666667" ixy="0" ixz="0" iyy="0.000182291666667" iyz="0" izz="0.00015625"/>
    </inertial>
  </link>
  <!--3rd joint: Upper-Lower -->
  <joint name="hinge_right_1_3" type="revolute">
    <parent link="serbo_right_1"/>
    <child link="link_right_1_lower"/>
    <origin rpy="0 1.5707 0" xyz="0 0 0"/>
    <axis xyz="1 0 0"/>
    <limit effort="1000" lower="-0.785" upper="0.785" velocity="100.0"/>
  </joint>
  <link name="link_right_1_lower">
    <inertial>
      <origin xyz="0 0 0.05"/>
      <mass value="2.0"/>
      <inertia ixx="0.00171666666667" ixy="0" ixz="0" iyy="0.00171666666667" iyz="0" izz="0.0001"/>
    </inertial>
    <collision>
      <origin rpy="0 0 0" xyz="0 0 0.05"/>
      <geometry>
        <cylinder length="0.1" radius="0.01"/>
      </geometry>
    </collision>
    <visual>
      <origin rpy="0 0 0" xyz="0 0 0.05"/>
      <geometry>
        <cylinder length="0.1" radius="0.01"/>
      </geometry>
      <material name="Gray"/>
    </visual>
  </link>
  <link name="ball_right_1">
    <visual>
      <geometry>
        <sphere radius="0.02"/>
      </geometry>
      <material name="Black"/>
    </visual>
    <collision>
      <origin rpy="0 0 0 " xyz="0 0 0"/>
      <geometry>
        <sphere radius="0.02"/>
      </geometry>
    </collision>
    <inertial>
      <origin xyz="0 0 0"/>
      <mass value="0.02"/>
      <inertia ixx="3.2e-06" ixy="0" ixz="0" iyy="3.2e-06" iyz="0" izz="3.2e-06"/>
    </inertial>
  </link>
  <joint name="ball_right_1_joint" type="fixed">
    <parent link="link_right_1_lower"/>
    <child link="ball_right_1"/>
    <origin rpy="0 0 0" xyz="0 0 0.1"/>
  </joint>
  <!--joint-->
  <!-- =========gazebo reference============ -->
  <gazebo reference="base_right_1">
    <selfCollide value="false"/>
    <material>Gazebo/Black</material>
    <turnGravityOff>false</turnGravityOff>
  </gazebo>
  <gazebo reference="link_right_1_lower">
    <selfCollide value="false"/>
    <mu1 value="10000.0"/>
    <mu2 value="10000.0"/>
    <kp value="10000000.0"/>
    <kd value="1.0"/>
    <fdir1 value="1 0 0"/>
    <material>Gazebo/Gray</material>
    <turnGravityOff>false</turnGravityOff>
  </gazebo>
  <gazebo reference="link_right_1_upper">
    <selfCollide value="false"/>
    <mu1 value="10000.0"/>
    <mu2 value="10000.0"/>
    <kp value="10000000.0"/>
    <kd value="1.0"/>
    <fdir1 value="1 0 0"/>
    <material>Gazebo/Gray</material>
    <turnGravityOff>false</turnGravityOff>
  </gazebo>
  <gazebo reference="ball_right_1">
    <selfCollide value="false"/>
    <mu1 value="10000.0"/>
    <mu2 value="10000.0"/>
    <kp value="10000000.0"/>
    <kd value="1.0"/>
    <fdir1 value="1 0 0"/>
    <material>Gazebo/Black</material>
    <turnGravityOff>false</turnGravityOff>
  </gazebo>
  <gazebo reference="serbo_right_1">
    <selfCollide value="false"/>
    <mu1 value="10000.0"/>
    <mu2 value="10000.0"/>
    <kp value="10000000.0"/>
    <kd value="1.0"/>
    <fdir1 value="1 0 0"/>
    <material>Gazebo/Black</material>
    <turnGravityOff>false</turnGravityOff>
  </gazebo>
  <!-- Transmission is important to link the joints and the controller -->
  <transmission name="hinge_right_1_1_trans">
    <type>transmission_interface/SimpleTransmission</type>
    <joint name="hinge_right_1_1">
      <hardwareInterface>hardware_interface/EffortJointInterface</hardwareInterface>
    </joint>
    <actuator name="hinge_right_1_1_motor">
      <mechanicalReduction>1</mechanicalReduction>
    </actuator>
  </transmission>
  <transmission name="hinge_right_1_2_trans">
    <type>transmission_interface/SimpleTransmission</type>
    <joint name="hinge_right_1_2">
      <hardwareInterface>hardware_interface/EffortJointInterface</hardwareInterface>
    </joint>
    <actuator name="hinge_right_1_2_motor">
      <mechanicalReduction>1</mechanicalReduction>
    </actuator>
  </transmission>
  <transmission name="hinge_right_1_3_trans">
    <type>transmission_interface/SimpleTransmission</type>
    <joint name="hinge_right_1_3">
      <hardwareInterface>hardware_interface/EffortJointInterface</hardwareInterface>
    </joint>
    <actuator name="hinge_right_1_3_motor">
      <mechanicalReduction>1</mechanicalReduction>
    </actuator>
  </transmission>
</robot>
